Workbook
Name Mapped_Owner: 'Mapped Opponent'!$B$4:$C$28

Sheet AllData
A1: Season | B1: Date | C1: Owner | D1: Team Name | E1: Team - Year | F1: QB | G1: Top RB | H1: Top WR | I1: TE | J1: Current Owner | K1: This Year | L1: Reg Season Finish | M1: Playoff Finish | N1: Finish | O1: Games Played | P1: Wins | Q1: Losses | R1: Final Points For | S1: Final Points Against | T1: City | U1: State | V1: ZIP | W1: Buy In | X1: $ Won | Y1: Profit | Z1: Championships | AA1: Playoff Appearances | AB1: Win Last Game? | AC1: Wins_PointsSort | AD1: Reg Season #1s | AE1: Reg Season Top Points | AF1: Power Rank Wins | AG1: Power Rank Losses | AH1: Power Rank GP | AI1: Rules | AJ1: Regular Season Pts Rank | AK1: Points For Index | AL1: Points Against Index | AM1: Weekly Top 6 Scores
A2: 2009 | B2: 39814 | C2: Hudspeath | D2: Cutler's Year | E2: =D2&" - "&A2 -> Cutler's Year - 2009 | F2: Tom Brady | G2: Ryan Grant | H2: Vincent Jackson | I2: Kellen Winslow | J2: Current Owner | L2: 2 | M2: 1 | N2: =M2 -> 1 | O2: 13 | P2: 9 | Q2: =13-P2 -> 4 | R2: 1329 | S2: 1234 | T2: Bloomington | U2: Indiana | V2: 47405 | W2: 25 | X2: 100 | Y2: =X2-W2 -> 75 | Z2: =IF(M2=1,1,0) -> 1 | AA2: =if(L2<7,1,0) -> 1 | AC2: =P2*100+R2/4 -> 1232.25 | AD2: =if(L2=1,1,0) -> 0 | AF2: =sumifs('WL Matrix 2'!T:T,'WL Matrix 2'!B:B,A2,'WL Matrix 2'!C:C,C2,'WL Matrix 2'!M:M,"Regular Season") -> 0 | AI2: No PPR | AJ2: =rank(R2,$R$2:$R$13) -> 2 | AK2: =R2/ averageif($A:$A,A2,R:R) -> 1.0749528 | AL2: =S2/averageif($A:$A,A2,S:S) -> 0.99817998 | AM2: =sumifs('WL Matrix 2'!T:T,'WL Matrix 2'!B:B,A2,'WL Matrix 2'!C:C,C2,'WL Matrix 2'!M:M,"Regular Season") -> 0
A3: 2009 | B3: 39814 | C3: Katz | D3: ak47 | E3: =D3&" - "&A3 -> ak47 - 2009 | F3: Kurt Warner | G3: Maurice Jones-Drew | H3: Steve Smith | I3: Dallas Clark | J3: Retired Owner | L3: 8 | M3: 2 | N3: =M3 -> 2 | O3: 13 | P3: 6 | Q3: =13-P3 -> 7 | R3: 1209 | S3: 1263 | T3: Bloomington | U3: Indiana | V3: 47405 | W3: 25 | X3: 60 | Y3: =X3-W3 -> 35 | Z3: =IF(M3=1,1,0) -> 0 | AA3: =if(L3<7,1,0) -> 0 | AC3: =P3*100+R3/4 -> 902.25 | AD3: =if(L3=1,1,0) -> 0 | AF3: =sumifs('WL Matrix 2'!T:T,'WL Matrix 2'!B:B,A3,'WL Matrix 2'!C:C,C3,'WL Matrix 2'!M:M,"Regular Season") -> 0 | AI3: No PPR | AJ3: =rank(R3,$R$2:$R$13) -> 9 | AK3: =R3/ averageif($A:$A,A3,R:R) -> 0.97789161 | AL3: =S3/averageif($A:$A,A3,S:S) -> 1.021638 | AM3: =sumifs('WL Matrix 2'!T:T,'WL Matrix 2'!B:B,A3,'WL Matrix 2'!C:C,C3,'WL Matrix 2'!M:M,"Regular Season") -> 0
A4: 2009 | B4: 39814 | C4: Tayski | D4: Brett Favre | E4: =D4&" - "&A4 -> Brett Favre - 2009 | F4: Drew Brees | G4: Joseph Addai | H4: DeSean Jackson | I4: Greg Olsen | J4: Current Owner | L4: 5 | M4: 3 | N4: =M4 -> 3 | O4: 13 | P4: 8 | Q4: =13-P4 -> 5 | R4: 1248 | S4: 1206 | T4: Bloomington | U4: Indiana | V4: 47405 | W4: 25 | X4: 25 | Y4: =X4-W4 -> 0 | Z4: =IF(M4=1,1,0) -> 0 | AA4: =if(L4<7,1,0) -> 1 | AC4: =P4*100+R4/4 -> 1112 | AD4: =if(L4=1,1,0) -> 0 | AF4: =sumifs('WL Matrix 2'!T:T,'WL Matrix 2'!B:B,A4,'WL Matrix 2'!C:C,C4,'WL Matrix 2'!M:M,"Regular Season") -> 0 | AI4: No PPR | AJ4: =rank(R4,$R$2:$R$13) -> 6 | AK4: =R4/ averageif($A:$A,A4,R:R) -> 1.0094365 | AL4: =S4/averageif($A:$A,A4,S:S) -> 0.97553084 | AM4: =sumifs('WL Matrix 2'!T:T,'WL Matrix 2'!B:B,A4,'WL Matrix 2'!C:C,C4,'WL Matrix 2'!M:M,"Regular Season") -> 0
A5: 2009 | B5: 39814 | C5: Salty | D5: Salt on My Knob | E5: =D5&" - "&A5 -> Salt on My Knob - 2009 | F5: Carson Palmer | G5: Laurence Maroney | H5: Andre Johnson | I5: Tony Gonzalez | J5: Current Owner | L5: 3 | M5: 4 | N5: =M5 -> 4 | O5: 13 | P5: 8 | Q5: =13-P5 -> 5 | R5: 1362 | S5: 1229 | T5: Bloomington | U5: Indiana | V5: 47405 | W5: 25 | X5: 40 | Y5: =X5-W5 -> 15 | Z5: =IF(M5=1,1,0) -> 0 | AA5: =if(L5<7,1,0) -> 1 | AC5: =P5*100+R5/4 -> 1140.5 | AD5: =if(L5=1,1,0) -> 0 | AE5: 1 | AF5: =sumifs('WL Matrix 2'!T:T,'WL Matrix 2'!B:B,A5,'WL Matrix 2'!C:C,C5,'WL Matrix 2'!M:M,"Regular Season") -> 0 | AI5: No PPR | AJ5: =rank(R5,$R$2:$R$13) -> 1 | AK5: =R5/ averageif($A:$A,A5,R:R) -> 1.1016446 | AL5: =S5/averageif($A:$A,A5,S:S) -> 0.99413549 | AM5: =sumifs('WL Matrix 2'!T:T,'WL Matrix 2'!B:B,A5,'WL Matrix 2'!C:C,C5,'WL Matrix 2'!M:M,"Regular Season") -> 0
A6: 2009 | B6: 39814 | C6: Rooney/Jackson | D6: Dawg's Gotta Eat | E6: =D6&" - "&A6 -> Dawg's Gotta Eat - 2009 | F6: Aaron Rodgers | G6: Adrian Peterson | H6: Calvin Johnson | I6: Visanthe Shiancoe | J6: Current Owner | L6: 4 | M6: 5 | N6: =M6 -> 5 | O6: 13 | P6: 8 | Q6: =13-P6 -> 5 | R6: 1327 | S6: 1179 | T6: Bloomington | U6: Indiana | V6: 47405 | W6: 25 | Y6: =X6-W6 -> -25 | Z6: =IF(M6=1,1,0) -> 0 | AA6: =if(L6<7,1,0) -> 1 | AC6: =P6*100+R6/4 -> 1131.75 | AD6: =if(L6=1,1,0) -> 0 | AF6: =sumifs('WL Matrix 2'!T:T,'WL Matrix 2'!B:B,A6,'WL Matrix 2'!C:C,C6,'WL Matrix 2'!M:M,"Regular Season") -> 0 | AI6: No PPR | AJ6: =rank(R6,$R$2:$R$13) -> 3 | AK6: =R6/ averageif($A:$A,A6,R:R) -> 1.0733351 | AL6: =S6/averageif($A:$A,A6,S:S) -> 0.9536906 | AM6: =sumifs('WL Matrix 2'!T:T,'WL Matrix 2'!B:B,A6,'WL Matrix 2'!C:C,C6,'WL Matrix 2'!M:M,"Regular Season") -> 0
A7: 2009 | B7: 39814 | C7: Tennyson | D7: Rob Brochocinco | E7: =D7&" - "&A7 -> Rob Brochocinco - 2009 | F7: Matt Ryan | G7: Jamaal Charles | H7: Reggie Wayne | I7: Fred Davis | J7: Retired Owner | L7: 6 | M7: 6 | N7: =M7 -> 6 | O7: 13 | P7: 6 | Q7: =13-P7 -> 7 | R7: 1251 | S7: 1334 | T7: Bloomington | U7: Indiana | V7: 47405 | W7: 25 | Y7: =X7-W7 -> -25 | Z7: =IF(M7=1,1,0) -> 0 | AA7: =if(L7<7,1,0) -> 1 | AC7: =P7*100+R7/4 -> 912.75 | AD7: =if(L7=1,1,0) -> 0 | AF7: =sumifs('WL Matrix 2'!T:T,'WL Matrix 2'!B:B,A7,'WL Matrix 2'!C:C,C7,'WL Matrix 2'!M:M,"Regular Season") -> 0 | AI7: No PPR | AJ7: =rank(R7,$R$2:$R$13) -> 5 | AK7: =R7/ averageif($A:$A,A7,R:R) -> 1.011863 | AL7: =S7/averageif($A:$A,A7,S:S) -> 1.0790698 | AM7: =sumifs('WL Matrix 2'!T:T,'WL Matrix 2'!B:B,A7,'WL Matrix 2'!C:C,C7,'WL Matrix 2'!M:M,"Regular Season") -> 0
A8: 2009 | B8: 39814 | C8: Fellows | D8: Frat Stars | E8: =D8&" - "&A8 -> Frat Stars - 2009 | F8: Brett Favre | G8: Michael Turner | H8: Santonio Holmes | I8: Jermichael Finley | J8: Retired Owner | L8: 1 | M8: 7 | N8: =M8 -> 7 | O8: 13 | P8: 10 | Q8: =13-P8 -> 3 | R8: 1317 | S8: 1206 | T8: Bloomington | U8: Indiana | V8: 47405 | W8: 25 | X8: 75 | Y8: =X8-W8 -> 50 | Z8: =IF(M8=1,1,0) -> 0 | AA8: =if(L8<7,1,0) -> 1 | AC8: =P8*100+R8/4 -> 1329.25 | AD8: =if(L8=1,1,0) -> 1 | AF8: =sumifs('WL Matrix 2'!T:T,'WL Matrix 2'!B:B,A8,'WL Matrix 2'!C:C,C8,'WL Matrix 2'!M:M,"Regular Season") -> 0 | AI8: No PPR | AJ8: =rank(R8,$R$2:$R$13) -> 4 | AK8: =R8/ averageif($A:$A,A8,R:R) -> 1.0652467 | AL8: =S8/averageif($A:$A,A8,S:S) -> 0.97553084 | AM8: =sumifs('WL Matrix 2'!T:T,'WL Matrix 2'!B:B,A8,'WL Matrix 2'!C:C,C8,'WL Matrix 2'!M:M,"Regular Season") -> 0
A9: 2009 | B9: 39814 | C9: Burgess | D9: Bro and Sixteen | E9: =D9&" - "&A9 -> Bro and Sixteen - 2009 | F9: Philip Rivers | G9: Thomas Jones | H9: Larry Fitzgerald | I9: Vernon Davis | J9: Retired Owner | L9: 7 | M9: 8 | N9: =M9 -> 8 | O9: 13 | P9: 6 | Q9: =13-P9 -> 7 | R9: 1238 | S9: 1170 | T9: Bloomington | U9: Indiana | V9: 47405 | W9: 25 | Y9: =X9-W9 -> -25 | Z9: =IF(M9=1,1,0) -> 0 | AA9: =if(L9<7,1,0) -> 0 | AC9: =P9*100+R9/4 -> 909.5 | AD9: =if(L9=1,1,0) -> 0 | AF9: =sumifs('WL Matrix 2'!T:T,'WL Matrix 2'!B:B,A9,'WL Matrix 2'!C:C,C9,'WL Matrix 2'!M:M,"Regular Season") -> 0 | AI9: No PPR | AJ9: =rank(R9,$R$2:$R$13) -> 7 | AK9: =R9/ averageif($A:$A,A9,R:R) -> 1.0013481 | AL9: =S9/averageif($A:$A,A9,S:S) -> 0.94641052 | AM9: =sumifs('WL Matrix 2'!T:T,'WL Matrix 2'!B:B,A9,'WL Matrix 2'!C:C,C9,'WL Matrix 2'!M:M,"Regular Season") -> 0
A10: 2009 | B10: 39814 | C10: Guckien | D10: Roon's Raging Broner | E10: =D10&" - "&A10 -> Roon's Raging Broner - 2009 | F10: Joe Flacco | G10: Frank Gore | H10: Miles Austin | I10: Dustin Keller | J10: Retired Owner | L10: 9 | M10: 9 | N10: =M10 -> 9 | O10: 13 | P10: 5 | Q10: =13-P10 -> 8 | R10: 1163 | S10: 1246 | T10: Bloomington | U10: Indiana | V10: 47405 | W10: 25 | Y10: =X10-W10 -> -25 | Z10: =IF(M10=1,1,0) -> 0 | AA10: =if(L10<7,1,0) -> 0 | AC10: =P10*100+R10/4 -> 790.75 | AD10: =if(L10=1,1,0) -> 0 | AF10: =sumifs('WL Matrix 2'!T:T,'WL Matrix 2'!B:B,A10,'WL Matrix 2'!C:C,C10,'WL Matrix 2'!M:M,"Regular Season") -> 0 | AI10: No PPR | AJ10: =rank(R10,$R$2:$R$13) -> 10 | AK10: =R10/ averageif($A:$A,A10,R:R) -> 0.94068482 | AL10: =S10/averageif($A:$A,A10,S:S) -> 1.0078868 | AM10: =sumifs('WL Matrix 2'!T:T,'WL Matrix 2'!B:B,A10,'WL Matrix 2'!C:C,C10,'WL Matrix 2'!M:M,"Regular Season") -> 0
A11: 2009 | B11: 39814 | C11: Pierson | D11: LiveTheDream01 | E11: =D11&" - "&A11 -> LiveTheDream01 - 2009 | F11: Peyton Manning | G11: Ricky Williams | H11: Sidney Rice | I11: Antonio Gates | J11: Current Owner | L11: 12 | M11: 12 | N11: =M11 -> 12 | O11: 13 | P11: 3 | Q11: =13-P11 -> 10 | R11: 1049 | S11: 1216 | T11: Bloomington | U11: Indiana | V11: 47405 | W11: 25 | Y11: =X11-W11 -> -25 | Z11: =IF(M11=1,1,0) -> 0 | AA11: =if(L11<7,1,0) -> 0 | AC11: =P11*100+R11/4 -> 562.25 | AD11: =if(L11=1,1,0) -> 0 | AF11: =sumifs('WL Matrix 2'!T:T,'WL Matrix 2'!B:B,A11,'WL Matrix 2'!C:C,C11,'WL Matrix 2'!M:M,"Regular Season") -> 0 | AI11: No PPR | AJ11: =rank(R11,$R$2:$R$13) -> 12 | AK11: =R11/ averageif($A:$A,A11,R:R) -> 0.84847668 | AL11: =S11/averageif($A:$A,A11,S:S) -> 0.98361982 | AM11: =sumifs('WL Matrix 2'!T:T,'WL Matrix 2'!B:B,A11,'WL Matrix 2'!C:C,C11,'WL Matrix 2'!M:M,"Regular Season") -> 0
A12: 2009 | B12: 39814 | C12: Shep | D12: Broseph | E12: =D12&" - "&A12 -> Broseph - 2009 | F12: Matt Schaub | G12: Chris Johnson | H12: Roddy White | I12: Zach Miller | J12: Current Owner | L12: 11 | M12: 11 | N12: =M12 -> 11 | O12: 13 | P12: 4 | Q12: =13-P12 -> 9 | R12: 1126 | S12: 1232 | T12: Bloomington | U12: Indiana | V12: 47405 | W12: 25 | Y12: =X12-W12 -> -25 | Z12: =IF(M12=1,1,0) -> 0 | AA12: =if(L12<7,1,0) -> 0 | AC12: =P12*100+R12/4 -> 681.5 | AD12: =if(L12=1,1,0) -> 0 | AF12: =sumifs('WL Matrix 2'!T:T,'WL Matrix 2'!B:B,A12,'WL Matrix 2'!C:C,C12,'WL Matrix 2'!M:M,"Regular Season") -> 0 | AI12: No PPR | AJ12: =rank(R12,$R$2:$R$13) -> 11 | AK12: =R12/ averageif($A:$A,A12,R:R) -> 0.91075762 | AL12: =S12/averageif($A:$A,A12,S:S) -> 0.99656218 | AM12: =sumifs('WL Matrix 2'!T:T,'WL Matrix 2'!B:B,A12,'WL Matrix 2'!C:C,C12,'WL Matrix 2'!M:M,"Regular Season") -> 0
A13: 2009 | B13: 39814 | C13: Austin Marshall | D13: N*gros | E13: =D13&" - "&A13 -> N*gros - 2009 | F13: Donovan McNabb | G13: Jonathan Stewart | H13: Steve Smith | I13: Jason Witten | J13: Retired Owner | L13: 10 | M13: 10 | N13: =M13 -> 10 | O13: 13 | P13: 5 | Q13: =13-P13 -> 8 | R13: 1217 | S13: 1320 | T13: Bloomington | U13: Indiana | V13: 47405 | W13: 25 | Y13: =X13-W13 -> -25 | Z13: =IF(M13=1,1,0) -> 0 | AA13: =if(L13<7,1,0) -> 0 | AC13: =P13*100+R13/4 -> 804.25 | AD13: =if(L13=1,1,0) -> 0 | AF13: =sumifs('WL Matrix 2'!T:T,'WL Matrix 2'!B:B,A13,'WL Matrix 2'!C:C,C13,'WL Matrix 2'!M:M,"Regular Season") -> 0 | AI13: No PPR | AJ13: =rank(R13,$R$2:$R$13) -> 8 | AK13: =R13/ averageif($A:$A,A13,R:R) -> 0.98436236 | AL13: =S13/averageif($A:$A,A13,S:S) -> 1.0677452 | AM13: =sumifs('WL Matrix 2'!T:T,'WL Matrix 2'!B:B,A13,'WL Matrix 2'!C:C,C13,'WL Matrix 2'!M:M,"Regular Season") -> 0
A14: 2010 | B14: 40179 | C14: Mac | D14: Bieber Fever | E14: =D14&" - "&A14 -> Bieber Fever - 2010 | F14: Michael Vick | G14: Peyton Hillis | H14: Mike Wallace | I14: Rob Gronkowski | J14: Retired Owner | L14: 6 | M14: 1 | N14: =M14 -> 1 | O14: 13 | P14: 6 | Q14: =13-P14 -> 7 | R14: 1224 | S14: 1139 | T14: Bloomington | U14: Indiana | V14: 47405 | W14: 25 | X14: 100 | Y14: =X14-W14 -> 75 | Z14: =IF(M14=1,1,0) -> 1 | AA14: =if(L14<7,1,0) -> 1 | AC14: =P14*100+R14/4 -> 906 | AD14: =if(L14=1,1,0) -> 0 | AF14: =sumifs('WL Matrix 2'!T:T,'WL Matrix 2'!B:B,A14,'WL Matrix 2'!C:C,C14,'WL Matrix 2'!M:M,"Regular Season") -> 0 | AI14: No PPR | AJ14: =rank(R14,$R$14:$R$25) -> 3 | AK14: =R14/ averageif($A:$A,A14,R:R) -> 1.0554757 | AL14: =S14/averageif($A:$A,A14,S:S) -> 0.98210821 | AM14: =sumifs('WL Matrix 2'!T:T,'WL Matrix 2'!B:B,A14,'WL Matrix 2'!C:C,C14,'WL Matrix 2'!M:M,"Regular Season") -> 0
A15: 2010 | B15: 40179 | C15: Hudspeath | D15: Cutler's Year | E15: =D15&" - "&A15 -> Cutler's Year - 2010 | F15: Phillip Rivers | G15: Maurice Jones-Drew | H15: Roddy White | I15: Tony Gonzalez | J15: Current Owner | L15: 1 | M15: 2 | N15: =M15 -> 2 | O15: 13 | P15: 11 | Q15: =13-P15 -> 2 | R15: 1334 | S15: 1068 | T15: Bloomington | U15: Indiana | V15: 47406 | W15: 25 | X15: =60+40+75 -> 175 | Y15: =X15-W15 -> 150 | Z15: =IF(M15=1,1,0) -> 0 | AA15: =if(L15<7,1,0) -> 1 | AC15: =P15*100+R15/4 -> 1433.5 | AD15: =if(L15=1,1,0) -> 1 | AE15: 1 | AF15: =sumifs('WL Matrix 2'!T:T,'WL Matrix 2'!B:B,A15,'WL Matrix 2'!C:C,C15,'WL Matrix 2'!M:M,"Regular Season") -> 0 | AI15: No PPR | AJ15: =rank(R15,$R$14:$R$25) -> 1 | AK15: =R15/ averageif($A:$A,A15,R:R) -> 1.1503306 | AL15: =S15/averageif($A:$A,A15,S:S) -> 0.92088812 | AM15: =sumifs('WL Matrix 2'!T:T,'WL Matrix 2'!B:B,A15,'WL Matrix 2'!C:C,C15,'WL Matrix 2'!M:M,"Regular Season") -> 0
A16: 2010 | B16: 40179 | C16: KnardDawg | D16: Buckeyes | E16: =D16&" - "&A16 -> Buckeyes - 2010 | F16: Carson Palmer | G16: Adrian Peterson | H16: Dwayne Bowe | I16: Zach Miller | J16: Current Owner | L16: 2 | M16: 3 | N16: =M16 -> 3 | O16: 13 | P16: 8 | Q16: =13-P16 -> 5 | R16: 1221 | S16: 1128 | T16: Bloomington | U16: Indiana | V16: 47406 | W16: 25 | X16: 25 | Y16: =X16-W16 -> 0 | Z16: =IF(M16=1,1,0) -> 0 | AA16: =if(L16<7,1,0) -> 1 | AC16: =P16*100+R16/4 -> 1105.25 | AD16: =if(L16=1,1,0) -> 0 | AF16: =sumifs('WL Matrix 2'!T:T,'WL Matrix 2'!B:B,A16,'WL Matrix 2'!C:C,C16,'WL Matrix 2'!M:M,"Regular Season") -> 0 | AI16: No PPR | AJ16: =rank(R16,$R$14:$R$25) -> 4 | AK16: =R16/ averageif($A:$A,A16,R:R) -> 1.0528888 | AL16: =S16/averageif($A:$A,A16,S:S) -> 0.97262341 | AM16: =sumifs('WL Matrix 2'!T:T,'WL Matrix 2'!B:B,A16,'WL Matrix 2'!C:C,C16,'WL Matrix 2'!M:M,"Regular Season") -> 0
A17: 2010 | B17: 40179 | C17: Tayski | D17: Fahv-Ray is My Padre | E17: =D17&" - "&A17 -> Fahv-Ray is My Padre - 2010 | F17: Matt Schaub | G17: Arian Foster | H17: Calvin Johnson | I17: Dustin Keller | J17: Current Owner | L17: 4 | M17: 4 | N17: =M17 -> 4 | O17: 13 | P17: 7 | Q17: =13-P17 -> 6 | R17: 1138 | S17: 1249 | T17: Bloomington | U17: Indiana | V17: 47406 | W17: 25 | Y17: =X17-W17 -> -25 | Z17: =IF(M17=1,1,0) -> 0 | AA17: =if(L17<7,1,0) -> 1 | AC17: =P17*100+R17/4 -> 984.5 | AD17: =if(L17=1,1,0) -> 0 | AF17: =sumifs('WL Matrix 2'!T:T,'WL Matrix 2'!B:B,A17,'WL Matrix 2'!C:C,C17,'WL Matrix 2'!M:M,"Regular Season") -> 0 | AI17: No PPR | AJ17: =rank(R17,$R$14:$R$25) -> 7 | AK17: =R17/ averageif($A:$A,A17,R:R) -> 0.98131647 | AL17: =S17/averageif($A:$A,A17,S:S) -> 1.0769562 | AM17: =sumifs('WL Matrix 2'!T:T,'WL Matrix 2'!B:B,A17,'WL Matrix 2'!C:C,C17,'WL Matrix 2'!M:M,"Regular Season") -> 0
A18: 2010 | B18: 40179 | C18: Salty | D18: Salt 'N' Peppers | E18: =D18&" - "&A18 -> Salt 'N' Peppers - 2010 | F18: Drew Brees | G18: Jamaal Charles | H18: Stevie Johnson | I18: Kellen Winslow | J18: Current Owner | L18: 3 | M18: 5 | N18: =M18 -> 5 | O18: 13 | P18: 7 | Q18: =13-P18 -> 6 | R18: 1237 | S18: 1157 | T18: Bloomington | U18: Indiana | V18: 47406 | W18: 25 | Y18: =X18-W18 -> -25 | Z18: =IF(M18=1,1,0) -> 0 | AA18: =if(L18<7,1,0) -> 1 | AC18: =P18*100+R18/4 -> 1009.25 | AD18: =if(L18=1,1,0) -> 0 | AF18: =sumifs('WL Matrix 2'!T:T,'WL Matrix 2'!B:B,A18,'WL Matrix 2'!C:C,C18,'WL Matrix 2'!M:M,"Regular Season") -> 0 | AI18: No PPR | AJ18: =rank(R18,$R$14:$R$25) -> 2 | AK18: =R18/ averageif($A:$A,A18,R:R) -> 1.0666858 | AL18: =S18/averageif($A:$A,A18,S:S) -> 0.9976288 | AM18: =sumifs('WL Matrix 2'!T:T,'WL Matrix 2'!B:B,A18,'WL Matrix 2'!C:C,C18,'WL Matrix 2'!M:M,"Regular Season") -> 0
A19: 2010 | B19: 40179 | C19: Cock | D19: Acochalypto | E19: =D19&" - "&A19 -> Acochalypto - 2010 | F19: Joe Flacco | G19: Ahmad Bradshaw | H19: Larry Fitzgerald | I19: Aaron Hernandez | J19: Current Owner | L19: 5 | M19: 6 | N19: =M19 -> 6 | O19: 13 | P19: 7 | Q19: =13-P19 -> 6 | R19: 1087 | S19: 1135 | T19: Bloomington | U19: Indiana | V19: 47406 | W19: 25 | Y19: =X19-W19 -> -25 | Z19: =IF(M19=1,1,0) -> 0 | AA19: =if(L19<7,1,0) -> 1 | AC19: =P19*100+R19/4 -> 971.75 | AD19: =if(L19=1,1,0) -> 0 | AF19: =sumifs('WL Matrix 2'!T:T,'WL Matrix 2'!B:B,A19,'WL Matrix 2'!C:C,C19,'WL Matrix 2'!M:M,"Regular Season") -> 0 | AI19: No PPR | AJ19: =rank(R19,$R$14:$R$25) -> 10 | AK19: =R19/ averageif($A:$A,A19,R:R) -> 0.93733832 | AL19: =S19/averageif($A:$A,A19,S:S) -> 0.97865919 | AM19: =sumifs('WL Matrix 2'!T:T,'WL Matrix 2'!B:B,A19,'WL Matrix 2'!C:C,C19,'WL Matrix 2'!M:M,"Regular Season") -> 0
A20: 2010 | B20: 40179 | C20: Pierson | D20: Deny Till You Die | E20: =D20&" - "&A20 -> Deny Till You Die - 2010 | F20: Eli Manning | G20: Chris Johnson | H20: Brandon Lloyd | I20: Greg Olsen | J20: Current Owner | L20: 7 | M20: 7 | N20: =M20 -> 7 | O20: 13 | P20: 5 | Q20: =13-P20 -> 8 | R20: 1130 | S20: 1153 | T20: Bloomington | U20: Indiana | V20: 47406 | W20: 25 | Y20: =X20-W20 -> -25 | Z20: =IF(M20=1,1,0) -> 0 | AA20: =if(L20<7,1,0) -> 0 | AC20: =P20*100+R20/4 -> 782.5 | AD20: =if(L20=1,1,0) -> 0 | AF20: =sumifs('WL Matrix 2'!T:T,'WL Matrix 2'!B:B,A20,'WL Matrix 2'!C:C,C20,'WL Matrix 2'!M:M,"Regular Season") -> 0 | AI20: No PPR | AJ20: =rank(R20,$R$14:$R$25) -> 8 | AK20: =R20/ averageif($A:$A,A20,R:R) -> 0.97441794 | AL20: =S20/averageif($A:$A,A20,S:S) -> 0.99417978 | AM20: =sumifs('WL Matrix 2'!T:T,'WL Matrix 2'!B:B,A20,'WL Matrix 2'!C:C,C20,'WL Matrix 2'!M:M,"Regular Season") -> 0
A21: 2010 | B21: 40179 | C21: Shep | D21: America's Team | E21: =D21&" - "&A21 -> America's Team - 2010 | F21: Peyton Manning | G21: BenJarvus Green-Ellis | H21: Braylon Edwards | I21: Jason Witten | J21: Current Owner | L21: 8 | M21: 8 | N21: =M21 -> 8 | O21: 13 | P21: 6 | Q21: =13-P21 -> 7 | R21: 1085 | S21: 1131 | T21: Bloomington | U21: Indiana | V21: 47406 | W21: 25 | Y21: =X21-W21 -> -25 | Z21: =IF(M21=1,1,0) -> 0 | AA21: =if(L21<7,1,0) -> 0 | AC21: =P21*100+R21/4 -> 871.25 | AD21: =if(L21=1,1,0) -> 0 | AF21: =sumifs('WL Matrix 2'!T:T,'WL Matrix 2'!B:B,A21,'WL Matrix 2'!C:C,C21,'WL Matrix 2'!M:M,"Regular Season") -> 0 | AI21: No PPR | AJ21: =rank(R21,$R$14:$R$25) -> 11 | AK21: =R21/ averageif($A:$A,A21,R:R) -> 0.93561368 | AL21: =S21/averageif($A:$A,A21,S:S) -> 0.97521017 | AM21: =sumifs('WL Matrix 2'!T:T,'WL Matrix 2'!B:B,A21,'WL Matrix 2'!C:C,C21,'WL Matrix 2'!M:M,"Regular Season") -> 0
A22: 2010 | B22: 40179 | C22: Buser | D22: Milledgevile Knights | E22: =D22&" - "&A22 -> Milledgevile Knights - 2010 | F22: Tom Brady | G22: Rashard Mendenhall | H22: DeSean Jackson | I22: Brandon Pettigrew | J22: Current Owner | L22: 9 | M22: 9 | N22: =M22 -> 9 | O22: 13 | P22: 5 | Q22: =13-P22 -> 8 | R22: 1163 | S22: 1214 | T22: Bloomington | U22: Indiana | V22: 47406 | W22: 25 | Y22: =X22-W22 -> -25 | Z22: =IF(M22=1,1,0) -> 0 | AA22: =if(L22<7,1,0) -> 0 | AC22: =P22*100+R22/4 -> 790.75 | AD22: =if(L22=1,1,0) -> 0 | AF22: =sumifs('WL Matrix 2'!T:T,'WL Matrix 2'!B:B,A22,'WL Matrix 2'!C:C,C22,'WL Matrix 2'!M:M,"Regular Season") -> 0 | AI22: No PPR | AJ22: =rank(R22,$R$14:$R$25) -> 5 | AK22: =R22/ averageif($A:$A,A22,R:R) -> 1.0028744 | AL22: =S22/averageif($A:$A,A22,S:S) -> 1.0467773 | AM22: =sumifs('WL Matrix 2'!T:T,'WL Matrix 2'!B:B,A22,'WL Matrix 2'!C:C,C22,'WL Matrix 2'!M:M,"Regular Season") -> 0
A23: 2010 | B23: 40179 | C23: Hobbs | D23: Ham Sobbs | E23: =D23&" - "&A23 -> Ham Sobbs - 2010 | F23: Jay Cutler | G23: Mike Tolbert | H23: Andre Johnson | I23: Vernon Davis | J23: Retired Owner | L23: 10 | M23: 10 | N23: =M23 -> 10 | O23: 13 | P23: 6 | Q23: =13-P23 -> 7 | R23: 1109 | S23: 1266 | T23: Bloomington | U23: Indiana | V23: 47405 | W23: 25 | Y23: =X23-W23 -> -25 | Z23: =IF(M23=1,1,0) -> 0 | AA23: =if(L23<7,1,0) -> 0 | AC23: =P23*100+R23/4 -> 877.25 | AD23: =if(L23=1,1,0) -> 0 | AF23: =sumifs('WL Matrix 2'!T:T,'WL Matrix 2'!B:B,A23,'WL Matrix 2'!C:C,C23,'WL Matrix 2'!M:M,"Regular Season") -> 0 | AI23: No PPR | AJ23: =rank(R23,$R$14:$R$25) -> 9 | AK23: =R23/ averageif($A:$A,A23,R:R) -> 0.95630928 | AL23: =S23/averageif($A:$A,A23,S:S) -> 1.0916146 | AM23: =sumifs('WL Matrix 2'!T:T,'WL Matrix 2'!B:B,A23,'WL Matrix 2'!C:C,C23,'WL Matrix 2'!M:M,"Regular Season") -> 0
A24: 2010 | B24: 40179 | C24: Rooney/Jackson | D24: The Dawgfather | E24: =D24&" - "&A24 -> The Dawgfather - 2010 | F24: Aaron Rodgers | G24: Ray Rice | H24: Jeremy Maclin | I24: Jacob Tamme | J24: Current Owner | L24: 11 | M24: 11 | N24: =M24 -> 11 | O24: 13 | P24: 5 | Q24: =13-P24 -> 8 | R24: 1155 | S24: 1227 | T24: Bloomington | U24: Indiana | V24: 47406 | W24: 25 | Y24: =X24-W24 -> -25 | Z24: =IF(M24=1,1,0) -> 0 | AA24: =if(L24<7,1,0) -> 0 | AC24: =P24*100+R24/4 -> 788.75 | AD24: =if(L24=1,1,0) -> 0 | AF24: =sumifs('WL Matrix 2'!T:T,'WL Matrix 2'!B:B,A24,'WL Matrix 2'!C:C,C24,'WL Matrix 2'!M:M,"Regular Season") -> 0 | AI24: No PPR | AJ24: =rank(R24,$R$14:$R$25) -> 6 | AK24: =R24/ averageif($A:$A,A24,R:R) -> 0.99597586 | AL24: =S24/averageif($A:$A,A24,S:S) -> 1.0579866 | AM24: =sumifs('WL Matrix 2'!T:T,'WL Matrix 2'!B:B,A24,'WL Matrix 2'!C:C,C24,'WL Matrix 2'!M:M,"Regular Season") -> 0
A25: 2010 | B25: 40179 | C25: Fellows | D25: Frat Stars II | E25: =D25&" - "&A25 -> Frat Stars II - 2010 | F25: Josh Freeman | G25: Brandon Jacobs | H25: Miles Austin | I25: Antonio Gates | J25: Retired Owner | L25: 12 | M25: 12 | N25: =M25 -> 12 | O25: 13 | P25: 5 | Q25: =13-P25 -> 8 | R25: 1033 | S25: 1050 | T25: Bloomington | U25: Indiana | V25: 47406 | W25: 25 | Y25: =X25-W25 -> -25 | Z25: =IF(M25=1,1,0) -> 0 | AA25: =if(L25<7,1,0) -> 0 | AC25: =P25*100+R25/4 -> 758.25 | AD25: =if(L25=1,1,0) -> 0 | AF25: =sumifs('WL Matrix 2'!T:T,'WL Matrix 2'!B:B,A25,'WL Matrix 2'!C:C,C25,'WL Matrix 2'!M:M,"Regular Season") -> 0 | AI25: No PPR | AJ25: =rank(R25,$R$14:$R$25) -> 12 | AK25: =R25/ averageif($A:$A,A25,R:R) -> 0.89077321 | AL25: =S25/averageif($A:$A,A25,S:S) -> 0.90536754 | AM25: =sumifs('WL Matrix 2'!T:T,'WL Matrix 2'!B:B,A25,'WL Matrix 2'!C:C,C25,'WL Matrix 2'!M:M,"Regular Season") -> 0
A26: 2011 | B26: 40544 | C26: Buser | D26: Yes We Cam | E26: =D26&" - "&A26 -> Yes We Cam - 2011 | F26: Cam Newton | G26: Chris Johnson | H26: Marques Colston | I26: Brent Celek | J26: Current Owner | L26: 2 | M26: 1 | N26: =M26 -> 1 | O26: 13 | P26: 9 | Q26: =13-P26 -> 4 | R26: 1229 | S26: 1308 | T26: London | U26: England | V26: London | W26: 25 | X26: 100 | Y26: =X26-W26 -> 75 | Z26: =IF(M26=1,1,0) -> 1 | AA26: =if(L26<7,1,0) -> 1 | AC26: =P26*100+R26/4 -> 1207.25 | AD26: =if(L26=1,1,0) -> 0 | AF26: =sumifs('WL Matrix 2'!T:T,'WL Matrix 2'!B:B,A26,'WL Matrix 2'!C:C,C26,'WL Matrix 2'!M:M,"Regular Season") -> 89 | AG26: =11*O26-AF26 -> 54 | AI26: No PPR | AJ26: =rank(R26,$R$26:$R$37) -> 4 | AK26: =R26/ averageif($A:$A,A26,R:R) -> 1.0676126 | AL26: =S26/averageif($A:$A,A26,S:S) -> 1.114377 | AM26: =sumifs('WL Matrix 2'!T:T,'WL Matrix 2'!B:B,A26,'WL Matrix 2'!C:C,C26,'WL Matrix 2'!M:M,"Regular Season") -> 89
A27: 2011 | B27: 40544 | C27: T-How | D27: Kibbles 'n Fitz | E27: =D27&" - "&A27 -> Kibbles 'n Fitz - 2011 | F27: Tono Romo | G27: Michael Turner | H27: Larry Fitzgerald | I27: Kellen Winslow | J27: Current Owner | L27: 4 | M27: 2 | N27: =M27 -> 2 | O27: 13 | P27: 8 | Q27: =13-P27 -> 5 | R27: 1100 | S27: 1114 | T27: Barcelona | U27: Spain | V27: Barcelona | W27: 25 | X27: 60 | Y27: =X27-W27 -> 35 | Z27: =IF(M27=1,1,0) -> 0 | AA27: =if(L27<7,1,0) -> 1 | AC27: =P27*100+R27/4 -> 1075 | AD27: =if(L27=1,1,0) -> 0 | AF27: =sumifs('WL Matrix 2'!T:T,'WL Matrix 2'!B:B,A27,'WL Matrix 2'!C:C,C27,'WL Matrix 2'!M:M,"Regular Season") -> 69 | AG27: =11*O27-AF27 -> 74 | AI27: No PPR | AJ27: =rank(R27,$R$26:$R$37) -> 9 | AK27: =R27/ averageif($A:$A,A27,R:R) -> 0.95555234 | AL27: =S27/averageif($A:$A,A27,S:S) -> 0.94909478 | AM27: =sumifs('WL Matrix 2'!T:T,'WL Matrix 2'!B:B,A27,'WL Matrix 2'!C:C,C27,'WL Matrix 2'!M:M,"Regular Season") -> 69
A28: 2011 | B28: 40544 | C28: Pierson | D28: Gambling Man | E28: =D28&" - "&A28 -> Gambling Man - 2011 | F28: Phillip Rivers | G28: Arian Foster | H28: Wes Welker | I28: Rob Gronkowski | J28: Current Owner | L28: 1 | M28: 3 | N28: =M28 -> 3 | O28: 13 | P28: 9 | Q28: =13-P28 -> 4 | R28: 1247 | S28: 1105 | T28: Bloomington | U28: Indiana | V28: 47406 | W28: 25 | X28: 100 | Y28: =X28-W28 -> 75 | Z28: =IF(M28=1,1,0) -> 0 | AA28: =if(L28<7,1,0) -> 1 | AC28: =P28*100+R28/4 -> 1211.75 | AD28: =if(L28=1,1,0) -> 1 | AF28: =sumifs('WL Matrix 2'!T:T,'WL Matrix 2'!B:B,A28,'WL Matrix 2'!C:C,C28,'WL Matrix 2'!M:M,"Regular Season") -> 88 | AG28: =11*O28-AF28 -> 55 | AI28: No PPR | AJ28: =rank(R28,$R$26:$R$37) -> 2 | AK28: =R28/ averageif($A:$A,A28,R:R) -> 1.0832489 | AL28: =S28/averageif($A:$A,A28,S:S) -> 0.94142705 | AM28: =sumifs('WL Matrix 2'!T:T,'WL Matrix 2'!B:B,A28,'WL Matrix 2'!C:C,C28,'WL Matrix 2'!M:M,"Regular Season") -> 88
A29: 2011 | B29: 40544 | C29: Salty | D29: Salt Bake City | E29: =D29&" - "&A29 -> Salt Bake City - 2011 | F29: Matthew Stafford | G29: Ray Rice | H29: Vincent Jackson | I29: Jason Witten | J29: Current Owner | L29: 3 | M29: 4 | N29: =M29 -> 4 | O29: 13 | P29: 8 | Q29: =13-P29 -> 5 | R29: 1308 | S29: 1090 | T29: London | U29: England | V29: London | W29: 25 | X29: 40 | Y29: =X29-W29 -> 15 | Z29: =IF(M29=1,1,0) -> 0 | AA29: =if(L29<7,1,0) -> 1 | AC29: =P29*100+R29/4 -> 1127 | AD29: =if(L29=1,1,0) -> 0 | AE29: 1 | AF29: =sumifs('WL Matrix 2'!T:T,'WL Matrix 2'!B:B,A29,'WL Matrix 2'!C:C,C29,'WL Matrix 2'!M:M,"Regular Season") -> 97 | AG29: =11*O29-AF29 -> 46 | AI29: No PPR | AJ29: =rank(R29,$R$26:$R$37) -> 1 | AK29: =R29/ averageif($A:$A,A29,R:R) -> 1.1362386 | AL29: =S29/averageif($A:$A,A29,S:S) -> 0.9286475 | AM29: =sumifs('WL Matrix 2'!T:T,'WL Matrix 2'!B:B,A29,'WL Matrix 2'!C:C,C29,'WL Matrix 2'!M:M,"Regular Season") -> 97
A30: 2011 | B30: 40544 | C30: Hudspeath | D30: Cutler's Year | E30: =D30&" - "&A30 -> Cutler's Year - 2011 | F30: Drew Brees | G30: Rashard Mendenhall | H30: Roddy White | I30: Tony Gonzalez | J30: Current Owner | L30: 6 | M30: 5 | N30: =M30 -> 5 | O30: 13 | P30: 7 | Q30: =13-P30 -> 6 | R30: 1227 | S30: 1236 | T30: Barcelona | U30: Spain | V30: Barcelona | W30: 25 | Y30: =X30-W30 -> -25 | Z30: =IF(M30=1,1,0) -> 0 | AA30: =if(L30<7,1,0) -> 1 | AC30: =P30*100+R30/4 -> 1006.75 | AD30: =if(L30=1,1,0) -> 0 | AF30: =sumifs('WL Matrix 2'!T:T,'WL Matrix 2'!B:B,A30,'WL Matrix 2'!C:C,C30,'WL Matrix 2'!M:M,"Regular Season") -> 84 | AG30: =11*O30-AF30 -> 59 | AI30: No PPR | AJ30: =rank(R30,$R$26:$R$37) -> 5 | AK30: =R30/ averageif($A:$A,A30,R:R) -> 1.0658752 | AL30: =S30/averageif($A:$A,A30,S:S) -> 1.0530351 | AM30: =sumifs('WL Matrix 2'!T:T,'WL Matrix 2'!B:B,A30,'WL Matrix 2'!C:C,C30,'WL Matrix 2'!M:M,"Regular Season") -> 84
A31: 2011 | B31: 40544 | C31: Shep | D31: Show me Your TDs | E31: =D31&" - "&A31 -> Show me Your TDs - 2011 | F31: Joe Flacco | G31: Reggie Bush | H31: Hakeem Nicks | I31: Jimmy Graham | J31: Current Owner | L31: 5 | M31: 6 | N31: =M31 -> 6 | O31: 13 | P31: 7 | Q31: =13-P31 -> 6 | R31: 1233 | S31: 1195 | T31: Bloomington | U31: Indiana | V31: 47406 | W31: 25 | Y31: =X31-W31 -> -25 | Z31: =IF(M31=1,1,0) -> 0 | AA31: =if(L31<7,1,0) -> 1 | AC31: =P31*100+R31/4 -> 1008.25 | AD31: =if(L31=1,1,0) -> 0 | AF31: =sumifs('WL Matrix 2'!T:T,'WL Matrix 2'!B:B,A31,'WL Matrix 2'!C:C,C31,'WL Matrix 2'!M:M,"Regular Season") -> 85 | AG31: =11*O31-AF31 -> 58 | AI31: No PPR | AJ31: =rank(R31,$R$26:$R$37) -> 3 | AK31: =R31/ averageif($A:$A,A31,R:R) -> 1.0710873 | AL31: =S31/averageif($A:$A,A31,S:S) -> 1.0181044 | AM31: =sumifs('WL Matrix 2'!T:T,'WL Matrix 2'!B:B,A31,'WL Matrix 2'!C:C,C31,'WL Matrix 2'!M:M,"Regular Season") -> 85
A32: 2011 | B32: 40544 | C32: Guckien | D32: The McRB is Back! | E32: =D32&" - "&A32 -> The McRB is Back! - 2011 | F32: Kevin Kolb | G32: LeSean McCoy | H32: Calvin Johnson | I32: Owen Daniels | J32: Retired Owner | L32: 7 | M32: 7 | N32: =M32 -> 7 | O32: 13 | P32: 7 | Q32: =13-P32 -> 6 | R32: 1193 | S32: 1161 | T32: Bloomington | U32: Indiana | V32: 47406 | W32: 25 | Y32: =X32-W32 -> -25 | Z32: =IF(M32=1,1,0) -> 0 | AA32: =if(L32<7,1,0) -> 0 | AC32: =P32*100+R32/4 -> 998.25 | AD32: =if(L32=1,1,0) -> 0 | AF32: =sumifs('WL Matrix 2'!T:T,'WL Matrix 2'!B:B,A32,'WL Matrix 2'!C:C,C32,'WL Matrix 2'!M:M,"Regular Season") -> 74 | AG32: =11*O32-AF32 -> 69 | AI32: No PPR | AJ32: =rank(R32,$R$26:$R$37) -> 6 | AK32: =R32/ averageif($A:$A,A32,R:R) -> 1.0363399 | AL32: =S32/averageif($A:$A,A32,S:S) -> 0.98913738 | AM32: =sumifs('WL Matrix 2'!T:T,'WL Matrix 2'!B:B,A32,'WL Matrix 2'!C:C,C32,'WL Matrix 2'!M:M,"Regular Season") -> 74
A33: 2011 | B33: 40544 | C33: KnardDawg | D33: Tat Five | E33: =D33&" - "&A33 -> Tat Five - 2011 | F33: Tom Brady | G33: Frank Gore | H33: Victor Cruz | I33: Vernon Davis | J33: Current Owner | L33: 8 | M33: 8 | N33: =M33 -> 8 | O33: 13 | P33: 6 | Q33: =13-P33 -> 7 | R33: 1148 | S33: 1146 | T33: Bloomington | U33: Indiana | V33: 47406 | W33: 25 | Y33: =X33-W33 -> -25 | Z33: =IF(M33=1,1,0) -> 0 | AA33: =if(L33<7,1,0) -> 0 | AC33: =P33*100+R33/4 -> 887 | AD33: =if(L33=1,1,0) -> 0 | AF33: =sumifs('WL Matrix 2'!T:T,'WL Matrix 2'!B:B,A33,'WL Matrix 2'!C:C,C33,'WL Matrix 2'!M:M,"Regular Season") -> 72 | AG33: =11*O33-AF33 -> 71 | AI33: No PPR | AJ33: =rank(R33,$R$26:$R$37) -> 8 | AK33: =R33/ averageif($A:$A,A33,R:R) -> 0.99724917 | AL33: =S33/averageif($A:$A,A33,S:S) -> 0.97635783 | AM33: =sumifs('WL Matrix 2'!T:T,'WL Matrix 2'!B:B,A33,'WL Matrix 2'!C:C,C33,'WL Matrix 2'!M:M,"Regular Season") -> 72
A34: 2011 | B34: 40544 | C34: Rooney/Jackson | D34: Clay Rodge | E34: =D34&" - "&A34 -> Clay Rodge - 2011 | F34: Aaron Rodgers | G34: Pierre Thomas | H34: Julio Jones | I34: Jermichael Finley | J34: Current Owner | L34: 9 | M34: 9 | N34: =M34 -> 9 | O34: 13 | P34: 5 | Q34: =13-P34 -> 8 | R34: 1151 | S34: 1194 | T34: Bloomington | U34: Indiana | V34: 47406 | W34: 25 | Y34: =X34-W34 -> -25 | Z34: =IF(M34=1,1,0) -> 0 | AA34: =if(L34<7,1,0) -> 0 | AC34: =P34*100+R34/4 -> 787.75 | AD34: =if(L34=1,1,0) -> 0 | AF34: =sumifs('WL Matrix 2'!T:T,'WL Matrix 2'!B:B,A34,'WL Matrix 2'!C:C,C34,'WL Matrix 2'!M:M,"Regular Season") -> 66 | AG34: =11*O34-AF34 -> 77 | AI34: No PPR | AJ34: =rank(R34,$R$26:$R$37) -> 7 | AK34: =R34/ averageif($A:$A,A34,R:R) -> 0.99985522 | AL34: =S34/averageif($A:$A,A34,S:S) -> 1.0172524 | AM34: =sumifs('WL Matrix 2'!T:T,'WL Matrix 2'!B:B,A34,'WL Matrix 2'!C:C,C34,'WL Matrix 2'!M:M,"Regular Season") -> 66
A35: 2011 | B35: 40544 | C35: Cock | D35: It's My Vick In A Box | E35: =D35&" - "&A35 -> It's My Vick In A Box - 2011 | F35: Ben Roethlisberger | G35: Marshawn Lynch | H35: Nate Burleson | I35: Antonio Gates | J35: Current Owner | L35: 10 | M35: 10 | N35: =M35 -> 10 | O35: 13 | P35: 5 | Q35: =13-P35 -> 8 | R35: 1037 | S35: 1187 | T35: Bloomington | U35: Indiana | V35: 47406 | W35: 25 | Y35: =X35-W35 -> -25 | Z35: =IF(M35=1,1,0) -> 0 | AA35: =if(L35<7,1,0) -> 0 | AC35: =P35*100+R35/4 -> 759.25 | AD35: =if(L35=1,1,0) -> 0 | AF35: =sumifs('WL Matrix 2'!T:T,'WL Matrix 2'!B:B,A35,'WL Matrix 2'!C:C,C35,'WL Matrix 2'!M:M,"Regular Season") -> 50 | AG35: =11*O35-AF35 -> 93 | AI35: No PPR | AJ35: =rank(R35,$R$26:$R$37) -> 11 | AK35: =R35/ averageif($A:$A,A35,R:R) -> 0.90082525 | AL35: =S35/averageif($A:$A,A35,S:S) -> 1.0112886 | AM35: =sumifs('WL Matrix 2'!T:T,'WL Matrix 2'!B:B,A35,'WL Matrix 2'!C:C,C35,'WL Matrix 2'!M:M,"Regular Season") -> 50
A36: 2011 | B36: 40544 | C36: Fellows | D36: Yo Adrian | E36: =D36&" - "&A36 -> Yo Adrian - 2011 | F36: Tim Tebow | G36: Ryan Mathews | H36: Andre Johnson | I36: Brandon Pettigrew | J36: Retired Owner | L36: 11 | M36: 11 | N36: =M36 -> 11 | O36: 13 | P36: 4 | Q36: =13-P36 -> 9 | R36: 1067 | S36: 1188 | T36: Bloomington | U36: Indiana | V36: 47406 | W36: 25 | Y36: =X36-W36 -> -25 | Z36: =IF(M36=1,1,0) -> 0 | AA36: =if(L36<7,1,0) -> 0 | AC36: =P36*100+R36/4 -> 666.75 | AD36: =if(L36=1,1,0) -> 0 | AF36: =sumifs('WL Matrix 2'!T:T,'WL Matrix 2'!B:B,A36,'WL Matrix 2'!C:C,C36,'WL Matrix 2'!M:M,"Regular Season") -> 59 | AG36: =11*O36-AF36 -> 84 | AI36: No PPR | AJ36: =rank(R36,$R$26:$R$37) -> 10 | AK36: =R36/ averageif($A:$A,A36,R:R) -> 0.92688577 | AL36: =S36/averageif($A:$A,A36,S:S) -> 1.0121406 | AM36: =sumifs('WL Matrix 2'!T:T,'WL Matrix 2'!B:B,A36,'WL Matrix 2'!C:C,C36,'WL Matrix 2'!M:M,"Regular Season") -> 59
A37: 2011 | B37: 40544 | C37: Tayski | D37: Team Weis | E37: =D37&" - "&A37 -> Team Weis - 2011 | F37: Matt Schaub | G37: Maurice Jones-Drew | H37: Jeremy Maclin | I37: Aaron Hernandez | J37: Current Owner | L37: 12 | M37: 12 | N37: =M37 -> 12 | O37: 13 | P37: 3 | Q37: =13-P37 -> 10 | R37: 874 | S37: 1161 | T37: Milan | U37: Italy | V37: Milan | W37: 25 | Y37: =X37-W37 -> -25 | Z37: =IF(M37=1,1,0) -> 0 | AA37: =if(L37<7,1,0) -> 0 | AC37: =P37*100+R37/4 -> 518.5 | AD37: =if(L37=1,1,0) -> 0 | AF37: =sumifs('WL Matrix 2'!T:T,'WL Matrix 2'!B:B,A37,'WL Matrix 2'!C:C,C37,'WL Matrix 2'!M:M,"Regular Season") -> 25 | AG37: =11*O37-AF37 -> 118 | AI37: No PPR | AJ37: =rank(R37,$R$26:$R$37) -> 12 | AK37: =R37/ averageif($A:$A,A37,R:R) -> 0.75922977 | AL37: =S37/averageif($A:$A,A37,S:S) -> 0.98913738 | AM37: =sumifs('WL Matrix 2'!T:T,'WL Matrix 2'!B:B,A37,'WL Matrix 2'!C:C,C37,'WL Matrix 2'!M:M,"Regular Season") -> 25
A38: 2012 | B38: 40909 | C38: KnardDawg | D38: For Shurmur | E38: =D38&" - "&A38 -> For Shurmur - 2012 | F38: Matt Ryan | G38: Marshawn Lynch | H38: AJ Green | I38: Aaron Hernandez | J38: Current Owner | L38: 2 | M38: 1 | N38: =M38 -> 1 | O38: 13 | P38: 9 | Q38: =13-P38 -> 4 | R38: 1245 | S38: 1147 | T38: Bloomington | U38: Indiana | V38: 47405 | W38: 50 | X38: 200 | Y38: =X38-W38 -> 150 | Z38: =IF(M38=1,1,0) -> 1 | AA38: =if(L38<7,1,0) -> 1 | AC38: =P38*100+R38/4 -> 1211.25 | AD38: =if(L38=1,1,0) -> 0 | AF38: =sumifs('WL Matrix 2'!T:T,'WL Matrix 2'!B:B,A38,'WL Matrix 2'!C:C,C38,'WL Matrix 2'!M:M,"Regular Season") -> 87 | AG38: =11*O38-AF38 -> 56 | AI38: No PPR | AJ38: =rank(R38,$R$38:$R$49) -> 2 | AK38: =R38/ averageif($A:$A,A38,R:R) -> 1.0454864 | AL38: =S38/averageif($A:$A,A38,S:S) -> 0.96325845 | AM38: =sumifs('WL Matrix 2'!T:T,'WL Matrix 2'!B:B,A38,'WL Matrix 2'!C:C,C38,'WL Matrix 2'!M:M,"Regular Season") -> 87
A39: 2012 | B39: 40909 | C39: Shep | D39: Rexual Feeling | E39: =D39&" - "&A39 -> Rexual Feeling - 2012 | F39: Ben Roethlisberger | G39: DeMarco Murrary | H39: Julio Jones | I39: Owen Daniels | J39: Current Owner | L39: 1 | M39: 2 | N39: =M39 -> 2 | O39: 13 | P39: 10 | Q39: =13-P39 -> 3 | R39: 1271 | S39: 1084 | T39: Bloomington | U39: Indiana | V39: 47408 | W39: 50 | X39: =150+100+100 -> 350 | Y39: =X39-W39 -> 300 | Z39: =IF(M39=1,1,0) -> 0 | AA39: =if(L39<7,1,0) -> 1 | AC39: =P39*100+R39/4 -> 1317.75 | AD39: =if(L39=1,1,0) -> 1 | AE39: 1 | AF39: =sumifs('WL Matrix 2'!T:T,'WL Matrix 2'!B:B,A39,'WL Matrix 2'!C:C,C39,'WL Matrix 2'!M:M,"Regular Season") -> 90 | AG39: =11*O39-AF39 -> 53 | AI39: No PPR | AJ39: =rank(R39,$R$38:$R$49) -> 1 | AK39: =R39/ averageif($A:$A,A39,R:R) -> 1.0673198 | AL39: =S39/averageif($A:$A,A39,S:S) -> 0.91035062 | AM39: =sumifs('WL Matrix 2'!T:T,'WL Matrix 2'!B:B,A39,'WL Matrix 2'!C:C,C39,'WL Matrix 2'!M:M,"Regular Season") -> 90
A40: 2012 | B40: 40909 | C40: Buser | D40: Yes We Camden Cutler | E40: =D40&" - "&A40 -> Yes We Camden Cutler - 2012 | F40: Cam Newton | G40: Doug Martin | H40: Steve Smith | I40: Jason Witten | J40: Current Owner | L40: 3 | M40: 3 | N40: =M40 -> 3 | O40: 13 | P40: 8 | Q40: =13-P40 -> 5 | R40: 1239 | S40: 1228 | T40: Bloomington | U40: Indiana | V40: 47408 | W40: 50 | X40: 50 | Y40: =X40-W40 -> 0 | Z40: =IF(M40=1,1,0) -> 0 | AA40: =if(L40<7,1,0) -> 1 | AC40: =P40*100+R40/4 -> 1109.75 | AD40: =if(L40=1,1,0) -> 0 | AF40: =sumifs('WL Matrix 2'!T:T,'WL Matrix 2'!B:B,A40,'WL Matrix 2'!C:C,C40,'WL Matrix 2'!M:M,"Regular Season") -> 83 | AG40: =11*O40-AF40 -> 60 | AI40: No PPR | AJ40: =rank(R40,$R$38:$R$49) -> 3 | AK40: =R40/ averageif($A:$A,A40,R:R) -> 1.0404479 | AL40: =S40/averageif($A:$A,A40,S:S) -> 1.0312828 | AM40: =sumifs('WL Matrix 2'!T:T,'WL Matrix 2'!B:B,A40,'WL Matrix 2'!C:C,C40,'WL Matrix 2'!M:M,"Regular Season") -> 83
...

Sheet WL Matrix 2
A1: YearOwnerWeek | B1: Year | C1: Owner | D1: Week | E1: Record | F1: Score | G1: Placeholder 2 | H1: Opponent | I1: Opponent Name | J1: Owner's Score | K1: Opponent's Score | L1: Result | M1: Game Type | N1: Mapped Opponent | O1: Week Number | P1: OpponentsSimplified Name | Q1: Week | R1: YearWeek | S1: Weekly Score Rank | T1: Power Rank Score (Wins) | U1: Power Rank Losses | V1: Annual avg score | W1: Score Index
A2: =B2&C2&O2 -> 2011Hudspeath15 | B2: 2011 | C2: Hudspeath | D2: Round 1 | E2: 42192 | F2: L 94.3-101.6 | G2: at | H2: Salt Bake City (9-5) | I2: R Saltiel | J2: 94.3 | K2: 101.6 | L2: =IF(LEFT(F2,1)="W",1,0) -> 0 | M2: =IF(ISNUMBER(SEARCH("Round",D2)),"Playoffs","Regular Season") -> Playoffs | N2: =IFERROR(VLOOKUP(I2,Mapped_Owner,2,0),"") -> Salty | O2: =VLOOKUP(D2,'Mapped Opponent'!$G$4:$H$22,2,0) -> 15 | Q2: ="Week "&O2 -> Week 15 | R2: =B2&D2 -> 2011Round 1 | S2: =IFERROR(__xludf.DUMMYFUNCTION("rank(J2,FILTER(J:J,R:R=R2))"),6.0) -> 6 | T2: =IFERROR(12-S2,0) -> 6 | U2: =12-T2 -> 6 | V2: =averageif(AllData!A:A,B2,AllData!R:R)/vlookup(B2,AllData!A:O,15,0) -> 88.551282
A3: =B3&C3&O3 -> 2011Salty15 | B3: 2011 | C3: Salty | D3: Round 1 | E3: 42252 | F3: W 101.6-94.3 | H3: Cutler's Year (7-7) | I3: matt hudspeath | J3: 101.6 | K3: 94.3 | L3: =IF(LEFT(F3,1)="W",1,0) -> 1 | M3: =IF(ISNUMBER(SEARCH("Round",D3)),"Playoffs","Regular Season") -> Playoffs | N3: =IFERROR(VLOOKUP(I3,Mapped_Owner,2,0),"") -> Hudspeath | O3: =VLOOKUP(D3,'Mapped Opponent'!$G$4:$H$22,2,0) -> 15 | Q3: ="Week "&O3 -> Week 15 | R3: =B3&D3 -> 2011Round 1 | S3: =IFERROR(__xludf.DUMMYFUNCTION("rank(J3,FILTER(J:J,R:R=R3))"),3.0) -> 3 | T3: =IFERROR(12-S3,0) -> 9 | U3: =12-T3 -> 3 | V3: =averageif(AllData!A:A,B3,AllData!R:R)/vlookup(B3,AllData!A:O,15,0) -> 88.551282
A4: =B4&C4&O4 -> 2011Fellows15 | B4: 2011 | C4: Fellows | D4: Round 1 | E4: 42104 | F4: L 88.3-114.4 | H4: Team Weis (4-10) | I4: Taylor Weis | J4: 88.3 | K4: 114.4 | L4: =IF(LEFT(F4,1)="W",1,0) -> 0 | M4: =IF(ISNUMBER(SEARCH("Round",D4)),"Playoffs","Regular Season") -> Playoffs | N4: =IFERROR(VLOOKUP(I4,Mapped_Owner,2,0),"") -> Tayski | O4: =VLOOKUP(D4,'Mapped Opponent'!$G$4:$H$22,2,0) -> 15 | Q4: ="Week "&O4 -> Week 15 | R4: =B4&D4 -> 2011Round 1 | S4: =IFERROR(__xludf.DUMMYFUNCTION("rank(J4,FILTER(J:J,R:R=R4))"),9.0) -> 9 | T4: =IFERROR(12-S4,0) -> 3 | U4: =12-T4 -> 9 | V4: =averageif(AllData!A:A,B4,AllData!R:R)/vlookup(B4,AllData!A:O,15,0) -> 88.551282
A5: =B5&C5&O5 -> 2011Shep15 | B5: 2011 | C5: Shep | D5: Round 1 | E5: 42192 | F5: L 98.6-114.9 | G5: at | H5: Kibbles 'n Fitz (9-5) | I5: Tyler Howard | J5: 98.6 | K5: 114.9 | L5: =IF(LEFT(F5,1)="W",1,0) -> 0 | M5: =IF(ISNUMBER(SEARCH("Round",D5)),"Playoffs","Regular Season") -> Playoffs | N5: =IFERROR(VLOOKUP(I5,Mapped_Owner,2,0),"") -> T-How | O5: =VLOOKUP(D5,'Mapped Opponent'!$G$4:$H$22,2,0) -> 15 | Q5: ="Week "&O5 -> Week 15 | R5: =B5&D5 -> 2011Round 1 | S5: =IFERROR(__xludf.DUMMYFUNCTION("rank(J5,FILTER(J:J,R:R=R5))"),4.0) -> 4 | T5: =IFERROR(12-S5,0) -> 8 | U5: =12-T5 -> 4 | V5: =averageif(AllData!A:A,B5,AllData!R:R)/vlookup(B5,AllData!A:O,15,0) -> 88.551282
A6: =B6&C6&O6 -> 2011Guckien15 | B6: 2011 | C6: Guckien | D6: Round 1 | E6: 42222 | F6: W 96.7-77.4 | H6: Tat Five (6-8) | I6: Alex Kinniard | J6: 96.7 | K6: 77.4 | L6: =IF(LEFT(F6,1)="W",1,0) -> 1 | M6: =IF(ISNUMBER(SEARCH("Round",D6)),"Playoffs","Regular Season") -> Playoffs | N6: =IFERROR(VLOOKUP(I6,Mapped_Owner,2,0),"") -> KnardDawg | O6: =VLOOKUP(D6,'Mapped Opponent'!$G$4:$H$22,2,0) -> 15 | Q6: ="Week "&O6 -> Week 15 | R6: =B6&D6 -> 2011Round 1 | S6: =IFERROR(__xludf.DUMMYFUNCTION("rank(J6,FILTER(J:J,R:R=R6))"),5.0) -> 5 | T6: =IFERROR(12-S6,0) -> 7 | U6: =12-T6 -> 5 | V6: =averageif(AllData!A:A,B6,AllData!R:R)/vlookup(B6,AllData!A:O,15,0) -> 88.551282
A7: =B7&C7&O7 -> 2011Rooney/Jackson15 | B7: 2011 | C7: Rooney/Jackson | D7: Round 1 | E7: 42163 | F7: W 92.1-88.5 | H7: It's My Vick In a Box! (5-9) | I7: Chris Cochrane | J7: 92.1 | K7: 88.5 | L7: =IF(LEFT(F7,1)="W",1,0) -> 1 | M7: =IF(ISNUMBER(SEARCH("Round",D7)),"Playoffs","Regular Season") -> Playoffs | N7: =IFERROR(VLOOKUP(I7,Mapped_Owner,2,0),"") -> Cock | O7: =VLOOKUP(D7,'Mapped Opponent'!$G$4:$H$22,2,0) -> 15 | Q7: ="Week "&O7 -> Week 15 | R7: =B7&D7 -> 2011Round 1 | S7: =IFERROR(__xludf.DUMMYFUNCTION("rank(J7,FILTER(J:J,R:R=R7))"),7.0) -> 7 | T7: =IFERROR(12-S7,0) -> 5 | U7: =12-T7 -> 7 | V7: =averageif(AllData!A:A,B7,AllData!R:R)/vlookup(B7,AllData!A:O,15,0) -> 88.551282
A8: =B8&C8&O8 -> 2011Buser15 | B8: 2011 | C8: Buser | D8: Round 1 | E8: 42251 | F8: 0 pts | H8: BYE | J8: 0 | K8: 0 | L8: =IF(LEFT(F8,1)="W",1,0) -> 0 | M8: =IF(ISNUMBER(SEARCH("Round",D8)),"Playoffs","Regular Season") -> Playoffs | N8: =IFERROR(VLOOKUP(I8,Mapped_Owner,2,0),"") -> BYE | O8: =VLOOKUP(D8,'Mapped Opponent'!$G$4:$H$22,2,0) -> 15 | Q8: ="Week "&O8 -> Week 15 | R8: =B8&D8 -> 2011Round 1 | S8: =IFERROR(__xludf.DUMMYFUNCTION("rank(J8,FILTER(J:J,R:R=R8))"),11.0) -> 11 | T8: =IFERROR(12-S8,0) -> 1 | U8: =12-T8 -> 11 | V8: =averageif(AllData!A:A,B8,AllData!R:R)/vlookup(B8,AllData!A:O,15,0) -> 88.551282
A9: =B9&C9&O9 -> 2011Pierson15 | B9: 2011 | C9: Pierson | D9: Round 1 | E9: 42251 | F9: 0 pts | H9: BYE | J9: 0 | K9: 0 | L9: =IF(LEFT(F9,1)="W",1,0) -> 0 | M9: =IF(ISNUMBER(SEARCH("Round",D9)),"Playoffs","Regular Season") -> Playoffs | N9: =IFERROR(VLOOKUP(I9,Mapped_Owner,2,0),"") -> BYE | O9: =VLOOKUP(D9,'Mapped Opponent'!$G$4:$H$22,2,0) -> 15 | Q9: ="Week "&O9 -> Week 15 | R9: =B9&D9 -> 2011Round 1 | S9: =IFERROR(__xludf.DUMMYFUNCTION("rank(J9,FILTER(J:J,R:R=R9))"),11.0) -> 11 | T9: =IFERROR(12-S9,0) -> 1 | U9: =12-T9 -> 11 | V9: =averageif(AllData!A:A,B9,AllData!R:R)/vlookup(B9,AllData!A:O,15,0) -> 88.551282
A10: =B10&C10&O10 -> 2011Cock15 | B10: 2011 | C10: Cock | D10: Round 1 | E10: 42133 | F10: L 88.5-92.1 | G10: at | H10: Clay Rodge (6-8) | I10: Stephen Rooney | J10: 88.5 | K10: 92.1 | L10: =IF(LEFT(F10,1)="W",1,0) -> 0 | M10: =IF(ISNUMBER(SEARCH("Round",D10)),"Playoffs","Regular Season") -> Playoffs | N10: =IFERROR(VLOOKUP(I10,Mapped_Owner,2,0),"") -> Rooney/Jackson | O10: =VLOOKUP(D10,'Mapped Opponent'!$G$4:$H$22,2,0) -> 15 | Q10: ="Week "&O10 -> Week 15 | R10: =B10&D10 -> 2011Round 1 | S10: =IFERROR(__xludf.DUMMYFUNCTION("rank(J10,FILTER(J:J,R:R=R10))"),8.0) -> 8 | T10: =IFERROR(12-S10,0) -> 4 | U10: =12-T10 -> 8 | V10: =averageif(AllData!A:A,B10,AllData!R:R)/vlookup(B10,AllData!A:O,15,0) -> 88.551282
A11: =B11&C11&O11 -> 2011Tayski15 | B11: 2011 | C11: Tayski | D11: Round 1 | E11: 42104 | F11: W 114.4-88.3 | G11: at | H11: Yo Adrian! (4-10) | I11: Michael Fellows | J11: 114.4 | K11: 88.3 | L11: =IF(LEFT(F11,1)="W",1,0) -> 1 | M11: =IF(ISNUMBER(SEARCH("Round",D11)),"Playoffs","Regular Season") -> Playoffs | N11: =IFERROR(VLOOKUP(I11,Mapped_Owner,2,0),"") -> Fellows | O11: =VLOOKUP(D11,'Mapped Opponent'!$G$4:$H$22,2,0) -> 15 | Q11: ="Week "&O11 -> Week 15 | R11: =B11&D11 -> 2011Round 1 | S11: =IFERROR(__xludf.DUMMYFUNCTION("rank(J11,FILTER(J:J,R:R=R11))"),2.0) -> 2 | T11: =IFERROR(12-S11,0) -> 10 | U11: =12-T11 -> 2 | V11: =averageif(AllData!A:A,B11,AllData!R:R)/vlookup(B11,AllData!A:O,15,0) -> 88.551282
A12: =B12&C12&O12 -> 2011KnardDawg15 | B12: 2011 | C12: KnardDawg | D12: Round 1 | E12: 42163 | F12: L 77.4-96.7 | G12: at | H12: The McRB is back! (8-6) | I12: Tyler Guckien | J12: 77.4 | K12: 96.7 | L12: =IF(LEFT(F12,1)="W",1,0) -> 0 | M12: =IF(ISNUMBER(SEARCH("Round",D12)),"Playoffs","Regular Season") -> Playoffs | N12: =IFERROR(VLOOKUP(I12,Mapped_Owner,2,0),"") -> Guckien | O12: =VLOOKUP(D12,'Mapped Opponent'!$G$4:$H$22,2,0) -> 15 | Q12: ="Week "&O12 -> Week 15 | R12: =B12&D12 -> 2011Round 1 | S12: =IFERROR(__xludf.DUMMYFUNCTION("rank(J12,FILTER(J:J,R:R=R12))"),10.0) -> 10 | T12: =IFERROR(12-S12,0) -> 2 | U12: =12-T12 -> 10 | V12: =averageif(AllData!A:A,B12,AllData!R:R)/vlookup(B12,AllData!A:O,15,0) -> 88.551282
A13: =B13&C13&O13 -> 2011T-How15 | B13: 2011 | C13: T-How | D13: Round 1 | E13: 42252 | F13: W 114.9-98.6 | H13: Show me your TDs (7-7) | I13: Jordan Shepherd | J13: 114.9 | K13: 98.6 | L13: =IF(LEFT(F13,1)="W",1,0) -> 1 | M13: =IF(ISNUMBER(SEARCH("Round",D13)),"Playoffs","Regular Season") -> Playoffs | N13: =IFERROR(VLOOKUP(I13,Mapped_Owner,2,0),"") -> Shep | O13: =VLOOKUP(D13,'Mapped Opponent'!$G$4:$H$22,2,0) -> 15 | Q13: ="Week "&O13 -> Week 15 | R13: =B13&D13 -> 2011Round 1 | S13: =IFERROR(__xludf.DUMMYFUNCTION("rank(J13,FILTER(J:J,R:R=R13))"),1.0) -> 1 | T13: =IFERROR(12-S13,0) -> 11 | U13: =12-T13 -> 1 | V13: =averageif(AllData!A:A,B13,AllData!R:R)/vlookup(B13,AllData!A:O,15,0) -> 88.551282
A14: =B14&C14&O14 -> 2011Hudspeath16 | B14: 2011 | C14: Hudspeath | D14: Round 2 | E14: 42223 | F14: W 139.1-72.4 | G14: at | H14: Show me your TDs (7-8) | I14: Jordan Shepherd | J14: 139.1 | K14: 72.4 | L14: =IF(LEFT(F14,1)="W",1,0) -> 1 | M14: =IF(ISNUMBER(SEARCH("Round",D14)),"Playoffs","Regular Season") -> Playoffs | N14: =IFERROR(VLOOKUP(I14,Mapped_Owner,2,0),"") -> Shep | O14: =VLOOKUP(D14,'Mapped Opponent'!$G$4:$H$22,2,0) -> 16 | Q14: ="Week "&O14 -> Week 16 | R14: =B14&D14 -> 2011Round 2 | S14: =IFERROR(__xludf.DUMMYFUNCTION("rank(J14,FILTER(J:J,R:R=R14))"),1.0) -> 1 | T14: =IFERROR(12-S14,0) -> 11 | U14: =12-T14 -> 1 | V14: =averageif(AllData!A:A,B14,AllData!R:R)/vlookup(B14,AllData!A:O,15,0) -> 88.551282
A15: =B15&C15&O15 -> 2011Salty16 | B15: 2011 | C15: Salty | D15: Round 2 | E15: 42253 | F15: L 51.8-99.7 | G15: at | H15: Yes We Cam (10-4) | I15: Ed Buser | J15: 51.8 | K15: 99.7 | L15: =IF(LEFT(F15,1)="W",1,0) -> 0 | M15: =IF(ISNUMBER(SEARCH("Round",D15)),"Playoffs","Regular Season") -> Playoffs | N15: =IFERROR(VLOOKUP(I15,Mapped_Owner,2,0),"") -> Buser | O15: =VLOOKUP(D15,'Mapped Opponent'!$G$4:$H$22,2,0) -> 16 | Q15: ="Week "&O15 -> Week 16 | R15: =B15&D15 -> 2011Round 2 | S15: =IFERROR(__xludf.DUMMYFUNCTION("rank(J15,FILTER(J:J,R:R=R15))"),12.0) -> 12 | T15: =IFERROR(12-S15,0) -> 0 | U15: =12-T15 -> 12 | V15: =averageif(AllData!A:A,B15,AllData!R:R)/vlookup(B15,AllData!A:O,15,0) -> 88.551282
A16: =B16&C16&O16 -> 2011Fellows16 | B16: 2011 | C16: Fellows | D16: Round 2 | E16: 42134 | F16: W 91.9-76.1 | G16: at | H16: It's My Vick In a Box! (5-10) | I16: Chris Cochrane | J16: 91.9 | K16: 76.1 | L16: =IF(LEFT(F16,1)="W",1,0) -> 1 | M16: =IF(ISNUMBER(SEARCH("Round",D16)),"Playoffs","Regular Season") -> Playoffs | N16: =IFERROR(VLOOKUP(I16,Mapped_Owner,2,0),"") -> Cock | O16: =VLOOKUP(D16,'Mapped Opponent'!$G$4:$H$22,2,0) -> 16 | Q16: ="Week "&O16 -> Week 16 | R16: =B16&D16 -> 2011Round 2 | S16: =IFERROR(__xludf.DUMMYFUNCTION("rank(J16,FILTER(J:J,R:R=R16))"),7.0) -> 7 | T16: =IFERROR(12-S16,0) -> 5 | U16: =12-T16 -> 7 | V16: =averageif(AllData!A:A,B16,AllData!R:R)/vlookup(B16,AllData!A:O,15,0) -> 88.551282
A17: =B17&C17&O17 -> 2011Shep16 | B17: 2011 | C17: Shep | D17: Round 2 | E17: 42193 | F17: L 72.4-139.1 | H17: Cutler's Year (8-7) | I17: matt hudspeath | J17: 72.4 | K17: 139.1 | L17: =IF(LEFT(F17,1)="W",1,0) -> 0 | M17: =IF(ISNUMBER(SEARCH("Round",D17)),"Playoffs","Regular Season") -> Playoffs | N17: =IFERROR(VLOOKUP(I17,Mapped_Owner,2,0),"") -> Hudspeath | O17: =VLOOKUP(D17,'Mapped Opponent'!$G$4:$H$22,2,0) -> 16 | Q17: ="Week "&O17 -> Week 16 | R17: =B17&D17 -> 2011Round 2 | S17: =IFERROR(__xludf.DUMMYFUNCTION("rank(J17,FILTER(J:J,R:R=R17))"),9.0) -> 9 | T17: =IFERROR(12-S17,0) -> 3 | U17: =12-T17 -> 9 | V17: =averageif(AllData!A:A,B17,AllData!R:R)/vlookup(B17,AllData!A:O,15,0) -> 88.551282
A18: =B18&C18&O18 -> 2011Guckien16 | B18: 2011 | C18: Guckien | D18: Round 2 | E18: 42253 | F18: W 118.2-92.3 | H18: Clay Rodge (6-9) | I18: Stephen Rooney | J18: 118.2 | K18: 92.3 | L18: =IF(LEFT(F18,1)="W",1,0) -> 1 | M18: =IF(ISNUMBER(SEARCH("Round",D18)),"Playoffs","Regular Season") -> Playoffs | N18: =IFERROR(VLOOKUP(I18,Mapped_Owner,2,0),"") -> Rooney/Jackson | O18: =VLOOKUP(D18,'Mapped Opponent'!$G$4:$H$22,2,0) -> 16 | Q18: ="Week "&O18 -> Week 16 | R18: =B18&D18 -> 2011Round 2 | S18: =IFERROR(__xludf.DUMMYFUNCTION("rank(J18,FILTER(J:J,R:R=R18))"),2.0) -> 2 | T18: =IFERROR(12-S18,0) -> 10 | U18: =12-T18 -> 2 | V18: =averageif(AllData!A:A,B18,AllData!R:R)/vlookup(B18,AllData!A:O,15,0) -> 88.551282
A19: =B19&C19&O19 -> 2011Rooney/Jackson16 | B19: 2011 | C19: Rooney/Jackson | D19: Round 2 | E19: 42164 | F19: L 92.3-118.2 | G19: at | H19: The McRB is back! (9-6) | I19: Tyler Guckien | J19: 92.3 | K19: 118.2 | L19: =IF(LEFT(F19,1)="W",1,0) -> 0 | M19: =IF(ISNUMBER(SEARCH("Round",D19)),"Playoffs","Regular Season") -> Playoffs | N19: =IFERROR(VLOOKUP(I19,Mapped_Owner,2,0),"") -> Guckien | O19: =VLOOKUP(D19,'Mapped Opponent'!$G$4:$H$22,2,0) -> 16 | Q19: ="Week "&O19 -> Week 16 | R19: =B19&D19 -> 2011Round 2 | S19: =IFERROR(__xludf.DUMMYFUNCTION("rank(J19,FILTER(J:J,R:R=R19))"),6.0) -> 6 | T19: =IFERROR(12-S19,0) -> 6 | U19: =12-T19 -> 6 | V19: =averageif(AllData!A:A,B19,AllData!R:R)/vlookup(B19,AllData!A:O,15,0) -> 88.551282
A20: =B20&C20&O20 -> 2011Buser16 | B20: 2011 | C20: Buser | D20: Round 2 | E20: 42281 | F20: W 99.7-51.8 | H20: Salt Bake City (9-6) | I20: R Saltiel | J20: 99.7 | K20: 51.8 | L20: =IF(LEFT(F20,1)="W",1,0) -> 1 | M20: =IF(ISNUMBER(SEARCH("Round",D20)),"Playoffs","Regular Season") -> Playoffs | N20: =IFERROR(VLOOKUP(I20,Mapped_Owner,2,0),"") -> Salty | O20: =VLOOKUP(D20,'Mapped Opponent'!$G$4:$H$22,2,0) -> 16 | Q20: ="Week "&O20 -> Week 16 | R20: =B20&D20 -> 2011Round 2 | S20: =IFERROR(__xludf.DUMMYFUNCTION("rank(J20,FILTER(J:J,R:R=R20))"),5.0) -> 5 | T20: =IFERROR(12-S20,0) -> 7 | U20: =12-T20 -> 5 | V20: =averageif(AllData!A:A,B20,AllData!R:R)/vlookup(B20,AllData!A:O,15,0) -> 88.551282
A21: =B21&C21&O21 -> 2011Pierson16 | B21: 2011 | C21: Pierson | D21: Round 2 | E21: 42252 | F21: L 67.9-109.9 | H21: Kibbles 'n Fitz (10-5) | I21: Tyler Howard | J21: 67.9 | K21: 109.9 | L21: =IF(LEFT(F21,1)="W",1,0) -> 0 | M21: =IF(ISNUMBER(SEARCH("Round",D21)),"Playoffs","Regular Season") -> Playoffs | N21: =IFERROR(VLOOKUP(I21,Mapped_Owner,2,0),"") -> T-How | O21: =VLOOKUP(D21,'Mapped Opponent'!$G$4:$H$22,2,0) -> 16 | Q21: ="Week "&O21 -> Week 16 | R21: =B21&D21 -> 2011Round 2 | S21: =IFERROR(__xludf.DUMMYFUNCTION("rank(J21,FILTER(J:J,R:R=R21))"),11.0) -> 11 | T21: =IFERROR(12-S21,0) -> 1 | U21: =12-T21 -> 11 | V21: =averageif(AllData!A:A,B21,AllData!R:R)/vlookup(B21,AllData!A:O,15,0) -> 88.551282
A22: =B22&C22&O22 -> 2011Cock16 | B22: 2011 | C22: Cock | D22: Round 2 | E22: 42134 | F22: L 76.1-91.9 | H22: Yo Adrian! (5-10) | I22: Michael Fellows | J22: 76.1 | K22: 91.9 | L22: =IF(LEFT(F22,1)="W",1,0) -> 0 | M22: =IF(ISNUMBER(SEARCH("Round",D22)),"Playoffs","Regular Season") -> Playoffs | N22: =IFERROR(VLOOKUP(I22,Mapped_Owner,2,0),"") -> Fellows | O22: =VLOOKUP(D22,'Mapped Opponent'!$G$4:$H$22,2,0) -> 16 | Q22: ="Week "&O22 -> Week 16 | R22: =B22&D22 -> 2011Round 2 | S22: =IFERROR(__xludf.DUMMYFUNCTION("rank(J22,FILTER(J:J,R:R=R22))"),8.0) -> 8 | T22: =IFERROR(12-S22,0) -> 4 | U22: =12-T22 -> 8 | V22: =averageif(AllData!A:A,B22,AllData!R:R)/vlookup(B22,AllData!A:O,15,0) -> 88.551282
A23: =B23&C23&O23 -> 2011Tayski16 | B23: 2011 | C23: Tayski | D23: Round 2 | E23: 42105 | F23: L 69.7-110.3 | G23: at | H23: Tat Five (7-8) | I23: Alex Kinniard | J23: 69.7 | K23: 110.3 | L23: =IF(LEFT(F23,1)="W",1,0) -> 0 | M23: =IF(ISNUMBER(SEARCH("Round",D23)),"Playoffs","Regular Season") -> Playoffs | N23: =IFERROR(VLOOKUP(I23,Mapped_Owner,2,0),"") -> KnardDawg | O23: =VLOOKUP(D23,'Mapped Opponent'!$G$4:$H$22,2,0) -> 16 | Q23: ="Week "&O23 -> Week 16 | R23: =B23&D23 -> 2011Round 2 | S23: =IFERROR(__xludf.DUMMYFUNCTION("rank(J23,FILTER(J:J,R:R=R23))"),10.0) -> 10 | T23: =IFERROR(12-S23,0) -> 2 | U23: =12-T23 -> 10 | V23: =averageif(AllData!A:A,B23,AllData!R:R)/vlookup(B23,AllData!A:O,15,0) -> 88.551282
A24: =B24&C24&O24 -> 2011KnardDawg16 | B24: 2011 | C24: KnardDawg | D24: Round 2 | E24: 42193 | F24: W 110.3-69.7 | H24: Team Weis (4-11) | I24: Taylor Weis | J24: 110.3 | K24: 69.7 | L24: =IF(LEFT(F24,1)="W",1,0) -> 1 | M24: =IF(ISNUMBER(SEARCH("Round",D24)),"Playoffs","Regular Season") -> Playoffs | N24: =IFERROR(VLOOKUP(I24,Mapped_Owner,2,0),"") -> Tayski | O24: =VLOOKUP(D24,'Mapped Opponent'!$G$4:$H$22,2,0) -> 16 | Q24: ="Week "&O24 -> Week 16 | R24: =B24&D24 -> 2011Round 2 | S24: =IFERROR(__xludf.DUMMYFUNCTION("rank(J24,FILTER(J:J,R:R=R24))"),3.0) -> 3 | T24: =IFERROR(12-S24,0) -> 9 | U24: =12-T24 -> 3 | V24: =averageif(AllData!A:A,B24,AllData!R:R)/vlookup(B24,AllData!A:O,15,0) -> 88.551282
A25: =B25&C25&O25 -> 2011T-How16 | B25: 2011 | C25: T-How | D25: Round 2 | E25: 42282 | F25: W 109.9-67.9 | G25: at | H25: Gambling Man (9-5) | I25: Pierson Curtis | J25: 109.9 | K25: 67.9 | L25: =IF(LEFT(F25,1)="W",1,0) -> 1 | M25: =IF(ISNUMBER(SEARCH("Round",D25)),"Playoffs","Regular Season") -> Playoffs | N25: =IFERROR(VLOOKUP(I25,Mapped_Owner,2,0),"") -> Pierson | O25: =VLOOKUP(D25,'Mapped Opponent'!$G$4:$H$22,2,0) -> 16 | Q25: ="Week "&O25 -> Week 16 | R25: =B25&D25 -> 2011Round 2 | S25: =IFERROR(__xludf.DUMMYFUNCTION("rank(J25,FILTER(J:J,R:R=R25))"),4.0) -> 4 | T25: =IFERROR(12-S25,0) -> 8 | U25: =12-T25 -> 4 | V25: =averageif(AllData!A:A,B25,AllData!R:R)/vlookup(B25,AllData!A:O,15,0) -> 88.551282
A26: =B26&C26&O26 -> 2011Hudspeath17 | B26: 2011 | C26: Hudspeath | D26: Round 3 | E26: 42254 | F26: W 123.3-93 | G26: at | H26: Show me your TDs (7-9) | I26: Jordan Shepherd | J26: 123.3 | K26: 93 | L26: =IF(LEFT(F26,1)="W",1,0) -> 1 | M26: =IF(ISNUMBER(SEARCH("Round",D26)),"Playoffs","Regular Season") -> Playoffs | N26: =IFERROR(VLOOKUP(I26,Mapped_Owner,2,0),"") -> Shep | O26: =VLOOKUP(D26,'Mapped Opponent'!$G$4:$H$22,2,0) -> 17 | Q26: ="Week "&O26 -> Week 17 | R26: =B26&D26 -> 2011Round 3 | S26: =IFERROR(__xludf.DUMMYFUNCTION("rank(J26,FILTER(J:J,R:R=R26))"),1.0) -> 1 | T26: =IFERROR(12-S26,0) -> 11 | U26: =12-T26 -> 1 | V26: =averageif(AllData!A:A,B26,AllData!R:R)/vlookup(B26,AllData!A:O,15,0) -> 88.551282
A27: =B27&C27&O27 -> 2011Salty17 | B27: 2011 | C27: Salty | D27: Round 3 | E27: 42254 | F27: L 76.6-103 | G27: at | H27: Gambling Man (10-5) | I27: Pierson Curtis | J27: 76.6 | K27: 103 | L27: =IF(LEFT(F27,1)="W",1,0) -> 0 | M27: =IF(ISNUMBER(SEARCH("Round",D27)),"Playoffs","Regular Season") -> Playoffs | N27: =IFERROR(VLOOKUP(I27,Mapped_Owner,2,0),"") -> Pierson | O27: =VLOOKUP(D27,'Mapped Opponent'!$G$4:$H$22,2,0) -> 17 | Q27: ="Week "&O27 -> Week 17 | R27: =B27&D27 -> 2011Round 3 | S27: =IFERROR(__xludf.DUMMYFUNCTION("rank(J27,FILTER(J:J,R:R=R27))"),8.0) -> 8 | T27: =IFERROR(12-S27,0) -> 4 | U27: =12-T27 -> 8 | V27: =averageif(AllData!A:A,B27,AllData!R:R)/vlookup(B27,AllData!A:O,15,0) -> 88.551282
A28: =B28&C28&O28 -> 2011Fellows17 | B28: 2011 | C28: Fellows | D28: Round 3 | E28: 42135 | F28: L 53.4-104.4 | G28: at | H28: Clay Rodge (7-9) | I28: Stephen Rooney | J28: 53.4 | K28: 104.4 | L28: =IF(LEFT(F28,1)="W",1,0) -> 0 | M28: =IF(ISNUMBER(SEARCH("Round",D28)),"Playoffs","Regular Season") -> Playoffs | N28: =IFERROR(VLOOKUP(I28,Mapped_Owner,2,0),"") -> Rooney/Jackson | O28: =VLOOKUP(D28,'Mapped Opponent'!$G$4:$H$22,2,0) -> 17 | Q28: ="Week "&O28 -> Week 17 | R28: =B28&D28 -> 2011Round 3 | S28: =IFERROR(__xludf.DUMMYFUNCTION("rank(J28,FILTER(J:J,R:R=R28))"),11.0) -> 11 | T28: =IFERROR(12-S28,0) -> 1 | U28: =12-T28 -> 11 | V28: =averageif(AllData!A:A,B28,AllData!R:R)/vlookup(B28,AllData!A:O,15,0) -> 88.551282
A29: =B29&C29&O29 -> 2011Shep17 | B29: 2011 | C29: Shep | D29: Round 3 | E29: 42194 | F29: L 93-123.3 | H29: Cutler's Year (9-7) | I29: matt hudspeath | J29: 93 | K29: 123.3 | L29: =IF(LEFT(F29,1)="W",1,0) -> 0 | M29: =IF(ISNUMBER(SEARCH("Round",D29)),"Playoffs","Regular Season") -> Playoffs | N29: =IFERROR(VLOOKUP(I29,Mapped_Owner,2,0),"") -> Hudspeath | O29: =VLOOKUP(D29,'Mapped Opponent'!$G$4:$H$22,2,0) -> 17 | Q29: ="Week "&O29 -> Week 17 | R29: =B29&D29 -> 2011Round 3 | S29: =IFERROR(__xludf.DUMMYFUNCTION("rank(J29,FILTER(J:J,R:R=R29))"),6.0) -> 6 | T29: =IFERROR(12-S29,0) -> 6 | U29: =12-T29 -> 6 | V29: =averageif(AllData!A:A,B29,AllData!R:R)/vlookup(B29,AllData!A:O,15,0) -> 88.551282
A30: =B30&C30&O30 -> 2011Guckien17 | B30: 2011 | C30: Guckien | D30: Round 3 | E30: 42254 | F30: L 74.7-106 | H30: Tat Five (8-8) | I30: Alex Kinniard | J30: 74.7 | K30: 106 | L30: =IF(LEFT(F30,1)="W",1,0) -> 0 | M30: =IF(ISNUMBER(SEARCH("Round",D30)),"Playoffs","Regular Season") -> Playoffs | N30: =IFERROR(VLOOKUP(I30,Mapped_Owner,2,0),"") -> KnardDawg | O30: =VLOOKUP(D30,'Mapped Opponent'!$G$4:$H$22,2,0) -> 17 | Q30: ="Week "&O30 -> Week 17 | R30: =B30&D30 -> 2011Round 3 | S30: =IFERROR(__xludf.DUMMYFUNCTION("rank(J30,FILTER(J:J,R:R=R30))"),9.0) -> 9 | T30: =IFERROR(12-S30,0) -> 3 | U30: =12-T30 -> 9 | V30: =averageif(AllData!A:A,B30,AllData!R:R)/vlookup(B30,AllData!A:O,15,0) -> 88.551282
A31: =B31&C31&O31 -> 2011Rooney/Jackson17 | B31: 2011 | C31: Rooney/Jackson | D31: Round 3 | E31: 42194 | F31: W 104.4-53.4 | H31: Yo Adrian! (5-11) | I31: Michael Fellows | J31: 104.4 | K31: 53.4 | L31: =IF(LEFT(F31,1)="W",1,0) -> 1 | M31: =IF(ISNUMBER(SEARCH("Round",D31)),"Playoffs","Regular Season") -> Playoffs | N31: =IFERROR(VLOOKUP(I31,Mapped_Owner,2,0),"") -> Fellows | O31: =VLOOKUP(D31,'Mapped Opponent'!$G$4:$H$22,2,0) -> 17 | Q31: ="Week "&O31 -> Week 17 | R31: =B31&D31 -> 2011Round 3 | S31: =IFERROR(__xludf.DUMMYFUNCTION("rank(J31,FILTER(J:J,R:R=R31))"),4.0) -> 4 | T31: =IFERROR(12-S31,0) -> 8 | U31: =12-T31 -> 4 | V31: =averageif(AllData!A:A,B31,AllData!R:R)/vlookup(B31,AllData!A:O,15,0) -> 88.551282
A32: =B32&C32&O32 -> 2011Buser17 | B32: 2011 | C32: Buser | D32: Round 3 | E32: 42312 | F32: W 105.3-71.9 | H32: Kibbles 'n Fitz (10-6) | I32: Tyler Howard | J32: 105.3 | K32: 71.9 | L32: =IF(LEFT(F32,1)="W",1,0) -> 1 | M32: =IF(ISNUMBER(SEARCH("Round",D32)),"Playoffs","Regular Season") -> Playoffs | N32: =IFERROR(VLOOKUP(I32,Mapped_Owner,2,0),"") -> T-How | O32: =VLOOKUP(D32,'Mapped Opponent'!$G$4:$H$22,2,0) -> 17 | Q32: ="Week "&O32 -> Week 17 | R32: =B32&D32 -> 2011Round 3 | S32: =IFERROR(__xludf.DUMMYFUNCTION("rank(J32,FILTER(J:J,R:R=R32))"),3.0) -> 3 | T32: =IFERROR(12-S32,0) -> 9 | U32: =12-T32 -> 3 | V32: =averageif(AllData!A:A,B32,AllData!R:R)/vlookup(B32,AllData!A:O,15,0) -> 88.551282
A33: =B33&C33&O33 -> 2011Pierson17 | B33: 2011 | C33: Pierson | D33: Round 3 | E33: 42282 | F33: W 103-76.6 | H33: Salt Bake City (9-7) | I33: R Saltiel | J33: 103 | K33: 76.6 | L33: =IF(LEFT(F33,1)="W",1,0) -> 1 | M33: =IF(ISNUMBER(SEARCH("Round",D33)),"Playoffs","Regular Season") -> Playoffs | N33: =IFERROR(VLOOKUP(I33,Mapped_Owner,2,0),"") -> Salty | O33: =VLOOKUP(D33,'Mapped Opponent'!$G$4:$H$22,2,0) -> 17 | Q33: ="Week "&O33 -> Week 17 | R33: =B33&D33 -> 2011Round 3 | S33: =IFERROR(__xludf.DUMMYFUNCTION("rank(J33,FILTER(J:J,R:R=R33))"),5.0) -> 5 | T33: =IFERROR(12-S33,0) -> 7 | U33: =12-T33 -> 5 | V33: =averageif(AllData!A:A,B33,AllData!R:R)/vlookup(B33,AllData!A:O,15,0) -> 88.551282
A34: =B34&C34&O34 -> 2011Cock17 | B34: 2011 | C34: Cock | D34: Round 3 | E34: 42135 | F34: L 44.6-80.1 | H34: Team Weis (5-11) | I34: Taylor Weis | J34: 44.6 | K34: 80.1 | L34: =IF(LEFT(F34,1)="W",1,0) -> 0 | M34: =IF(ISNUMBER(SEARCH("Round",D34)),"Playoffs","Regular Season") -> Playoffs | N34: =IFERROR(VLOOKUP(I34,Mapped_Owner,2,0),"") -> Tayski | O34: =VLOOKUP(D34,'Mapped Opponent'!$G$4:$H$22,2,0) -> 17 | Q34: ="Week "&O34 -> Week 17 | R34: =B34&D34 -> 2011Round 3 | S34: =IFERROR(__xludf.DUMMYFUNCTION("rank(J34,FILTER(J:J,R:R=R34))"),12.0) -> 12 | T34: =IFERROR(12-S34,0) -> 0 | U34: =12-T34 -> 12 | V34: =averageif(AllData!A:A,B34,AllData!R:R)/vlookup(B34,AllData!A:O,15,0) -> 88.551282
